<sdf version='1.4'>
  <world name='default'>
    <light name='sun' type='directional'>
      <cast_shadows>1</cast_shadows>
      <pose>0 0 10 0 -0 0</pose>
      <diffuse>0.8 0.8 0.8 1</diffuse>
      <specular>0.2 0.2 0.2 1</specular>
      <attenuation>
        <range>1000</range>
        <constant>0.9</constant>
        <linear>0.01</linear>
        <quadratic>0.001</quadratic>
      </attenuation>
      <direction>-0.5 0.1 -0.9</direction>
    </light>
    <model name='ground_plane'>
      <static>1</static>
      <link name='link'>
        <collision name='collision'>
          <geometry>
            <plane>
              <normal>0 0 1</normal>
              <size>100 100</size>
            </plane>
          </geometry>
          <surface>
            <friction>
              <ode>
                <mu>100</mu>
                <mu2>50</mu2>
              </ode>
            </friction>
            <bounce/>
            <contact>
              <ode/>
            </contact>
          </surface>
          <max_contacts>10</max_contacts>
        </collision>
        <visual name='visual'>
          <cast_shadows>0</cast_shadows>
          <geometry>
            <plane>
              <normal>0 0 1</normal>
              <size>100 100</size>
            </plane>
          </geometry>
          <material>
            <script>
              <uri>file://media/materials/scripts/gazebo.material</uri>
              <name>Gazebo/Grey</name>
            </script>
          </material>
        </visual>
        <velocity_decay>
          <linear>0</linear>
          <angular>0</angular>
        </velocity_decay>
        <self_collide>0</self_collide>
        <kinematic>0</kinematic>
        <gravity>1</gravity>
      </link>
    </model>
    <physics type='ode'>
      <max_step_size>0.001</max_step_size>
      <real_time_factor>1</real_time_factor>
      <real_time_update_rate>1000</real_time_update_rate>
      <gravity>0 0 -9.8</gravity>
    </physics>
    <scene>
      <ambient>0.4 0.4 0.4 1</ambient>
      <background>0.7 0.7 0.7 1</background>
      <shadows>1</shadows>
    </scene>
    <spherical_coordinates>
      <surface_model>EARTH_WGS84</surface_model>
      <latitude_deg>0</latitude_deg>
      <longitude_deg>0</longitude_deg>
      <elevation>0</elevation>
      <heading_deg>0</heading_deg>
    </spherical_coordinates>
    <model name='roverfinal'>
      <link name='rov'>
        <pose>0 0 0 0 -0 0</pose>
        <inertial>
          <pose>0 0 0 0 -0 0</pose>
          <mass>4.39169</mass>
          <inertia>
            <ixx>0.199357</ixx>
            <ixy>-3.6151e-05</ixy>
            <ixz>0.00940668</ixz>
            <iyy>0.208149</iyy>
            <iyz>-1.43928e-07</iyz>
            <izz>0.306773</izz>
          </inertia>
        </inertial>
        <collision name='rov_collision'>
          <pose>0 0 0 0 -0 0</pose>
          <geometry>
            <mesh>
              <scale>1 1 1</scale>
              <uri>/home/daniela/proyrover_ws/src/roverfinal/meshes/rov.STL</uri>
            </mesh>
          </geometry>
          <max_contacts>10</max_contacts>
          <surface>
            <bounce/>
            <friction>
              <ode/>
            </friction>
            <contact>
              <ode/>
            </contact>
          </surface>
        </collision>
        <visual name='rov_visual'>
          <pose>0 0 0 0 -0 0</pose>
          <geometry>
            <mesh>
              <scale>1 1 1</scale>
              <uri>/home/daniela/proyrover_ws/src/roverfinal/meshes/rov.STL</uri>
            </mesh>
          </geometry>
        </visual>
        <velocity_decay>
          <linear>0</linear>
          <angular>0</angular>
        </velocity_decay>
        <self_collide>0</self_collide>
        <kinematic>0</kinematic>
        <gravity>1</gravity>
      </link>
      <link name='rueda1'>
        <pose>0.39573 -0.30621 0.12581 1.5708 -0 0</pose>
        <inertial>
          <pose>7.60404e-06 6.62674e-06 0.00062166 0 -0 0</pose>
          <mass>3.68718</mass>
          <inertia>
            <ixx>0.0186305</ixx>
            <ixy>-9.47267e-08</ixy>
            <ixz>9.82909e-06</ixz>
            <iyy>0.0186303</iyy>
            <iyz>8.11534e-06</iyz>
            <izz>0.0288597</izz>
          </inertia>
        </inertial>
        <collision name='rueda1_collision'>
          <pose>0 0 0 0 -0 0</pose>
          <geometry>
            <mesh>
              <scale>1 1 1</scale>
              <uri>/home/daniela/proyrover_ws/src/roverfinal/meshes/rueda1.STL</uri>
            </mesh>
          </geometry>
          <max_contacts>10</max_contacts>
          <surface>
            <bounce/>
            <friction>
              <ode/>
            </friction>
            <contact>
              <ode/>
            </contact>
          </surface>
        </collision>
        <visual name='rueda1_visual'>
          <pose>0 0 0 0 -0 0</pose>
          <geometry>
            <mesh>
              <scale>1 1 1</scale>
              <uri>/home/daniela/proyrover_ws/src/roverfinal/meshes/rueda1.STL</uri>
            </mesh>
          </geometry>
        </visual>
        <velocity_decay>
          <linear>0</linear>
          <angular>0</angular>
        </velocity_decay>
        <self_collide>0</self_collide>
        <kinematic>0</kinematic>
        <gravity>1</gravity>
      </link>
      <joint name='rueda_1' type='revolute'>
        <child>rueda1</child>
        <parent>rov</parent>
        <axis>
          <xyz>0 -1 -4e-06</xyz>
          <limit>
            <lower>-15</lower>
            <upper>15</upper>
            <effort>1000</effort>
            <velocity>0.5</velocity>
          </limit>
          <dynamics/>
        </axis>
      </joint>
      <link name='rueda2'>
        <pose>0.39573 0.30621 0.12581 1.5708 -0 0</pose>
        <inertial>
          <pose>2.1295e-06 -9.7362e-06 -0.00062151 0 -0 0</pose>
          <mass>3.6872</mass>
          <inertia>
            <ixx>0.018631</ixx>
            <ixy>-8.0891e-08</ixy>
            <ixz>-2.7061e-06</ixz>
            <iyy>0.01863</iyy>
            <iyz>1.2466e-05</iyz>
            <izz>0.02886</izz>
          </inertia>
        </inertial>
        <collision name='rueda2_collision'>
          <pose>0 0 0 0 -0 0</pose>
          <geometry>
            <mesh>
              <scale>1 1 1</scale>
              <uri>/home/daniela/proyrover_ws/src/roverfinal/meshes/rueda2.STL</uri>
            </mesh>
          </geometry>
          <max_contacts>10</max_contacts>
          <surface>
            <bounce/>
            <friction>
              <ode/>
            </friction>
            <contact>
              <ode/>
            </contact>
          </surface>
        </collision>
        <visual name='rueda2_visual'>
          <pose>0 0 0 0 -0 0</pose>
          <geometry>
            <mesh>
              <scale>1 1 1</scale>
              <uri>/home/daniela/proyrover_ws/src/roverfinal/meshes/rueda2.STL</uri>
            </mesh>
          </geometry>
        </visual>
        <velocity_decay>
          <linear>0</linear>
          <angular>0</angular>
        </velocity_decay>
        <self_collide>0</self_collide>
        <kinematic>0</kinematic>
        <gravity>1</gravity>
      </link>
      <joint name='rueda_2' type='revolute'>
        <child>rueda2</child>
        <parent>rov</parent>
        <axis>
          <xyz>0 -1 -4e-06</xyz>
          <limit>
            <lower>-15</lower>
            <upper>15</upper>
            <effort>1000</effort>
            <velocity>0.5</velocity>
          </limit>
          <dynamics/>
        </axis>
      </joint>
      <link name='rueda3'>
        <pose>0.090614 -0.30621 0.12581 1.5708 -0 0</pose>
        <inertial>
          <pose>9.2261e-06 1.3068e-06 0.00062028 0 -0 0</pose>
          <mass>3.6873</mass>
          <inertia>
            <ixx>0.018631</ixx>
            <ixy>-1.3252e-07</ixy>
            <ixz>1.1952e-05</ixz>
            <iyy>0.018631</iyy>
            <iyz>4.1426e-06</iyz>
            <izz>0.02886</izz>
          </inertia>
        </inertial>
        <collision name='rueda3_collision'>
          <pose>0 0 0 0 -0 0</pose>
          <geometry>
            <mesh>
              <scale>1 1 1</scale>
              <uri>/home/daniela/proyrover_ws/src/roverfinal/meshes/rueda3.STL</uri>
            </mesh>
          </geometry>
          <max_contacts>10</max_contacts>
          <surface>
            <bounce/>
            <friction>
              <ode/>
            </friction>
            <contact>
              <ode/>
            </contact>
          </surface>
        </collision>
        <visual name='rueda3_visual'>
          <pose>0 0 0 0 -0 0</pose>
          <geometry>
            <mesh>
              <scale>1 1 1</scale>
              <uri>/home/daniela/proyrover_ws/src/roverfinal/meshes/rueda3.STL</uri>
            </mesh>
          </geometry>
        </visual>
        <velocity_decay>
          <linear>0</linear>
          <angular>0</angular>
        </velocity_decay>
        <self_collide>0</self_collide>
        <kinematic>0</kinematic>
        <gravity>1</gravity>
      </link>
      <joint name='rueda_3' type='revolute'>
        <child>rueda3</child>
        <parent>rov</parent>
        <axis>
          <xyz>0 -1 -4e-06</xyz>
          <limit>
            <lower>-15</lower>
            <upper>15</upper>
            <effort>1000</effort>
            <velocity>0.5</velocity>
          </limit>
          <dynamics/>
        </axis>
      </joint>
      <link name='rueda4'>
        <pose>0.090612 0.30621 0.12581 1.5708 -0 0</pose>
        <inertial>
          <pose>3.8713e-06 -9.0806e-06 -0.00062179 0 -0 0</pose>
          <mass>3.6872</mass>
          <inertia>
            <ixx>0.018631</ixx>
            <ixy>1.4389e-08</ixy>
            <ixz>-5.2116e-06</ixz>
            <iyy>0.01863</iyy>
            <iyz>1.1701e-05</iyz>
            <izz>0.02886</izz>
          </inertia>
        </inertial>
        <collision name='rueda4_collision'>
          <pose>0 0 0 0 -0 0</pose>
          <geometry>
            <mesh>
              <scale>1 1 1</scale>
              <uri>/home/daniela/proyrover_ws/src/roverfinal/meshes/rueda4.STL</uri>
            </mesh>
          </geometry>
          <max_contacts>10</max_contacts>
          <surface>
            <bounce/>
            <friction>
              <ode/>
            </friction>
            <contact>
              <ode/>
            </contact>
          </surface>
        </collision>
        <visual name='rueda4_visual'>
          <pose>0 0 0 0 -0 0</pose>
          <geometry>
            <mesh>
              <scale>1 1 1</scale>
              <uri>/home/daniela/proyrover_ws/src/roverfinal/meshes/rueda4.STL</uri>
            </mesh>
          </geometry>
        </visual>
        <velocity_decay>
          <linear>0</linear>
          <angular>0</angular>
        </velocity_decay>
        <self_collide>0</self_collide>
        <kinematic>0</kinematic>
        <gravity>1</gravity>
      </link>
      <joint name='rueda_4' type='revolute'>
        <child>rueda4</child>
        <parent>rov</parent>
        <axis>
          <xyz>0 -1 -4e-06</xyz>
          <limit>
            <lower>-15</lower>
            <upper>15</upper>
            <effort>1000</effort>
            <velocity>0.5</velocity>
          </limit>
          <dynamics/>
        </axis>
      </joint>
      <link name='rueda5'>
        <pose>-0.39373 -0.30621 0.12581 1.5708 -0 0</pose>
        <inertial>
          <pose>2.2834e-06 -9.3615e-06 0.00061913 0 -0 0</pose>
          <mass>3.6872</mass>
          <inertia>
            <ixx>0.018631</ixx>
            <ixy>1.4376e-07</ixy>
            <ixz>2.2094e-06</ixz>
            <iyy>0.018631</iyy>
            <iyz>-1.2381e-05</iyz>
            <izz>0.02886</izz>
          </inertia>
        </inertial>
        <collision name='rueda5_collision'>
          <pose>0 0 0 0 -0 0</pose>
          <geometry>
            <mesh>
              <scale>1 1 1</scale>
              <uri>/home/daniela/proyrover_ws/src/roverfinal/meshes/rueda5.STL</uri>
            </mesh>
          </geometry>
          <max_contacts>10</max_contacts>
          <surface>
            <bounce/>
            <friction>
              <ode/>
            </friction>
            <contact>
              <ode/>
            </contact>
          </surface>
        </collision>
        <visual name='rueda5_visual'>
          <pose>0 0 0 0 -0 0</pose>
          <geometry>
            <mesh>
              <scale>1 1 1</scale>
              <uri>/home/daniela/proyrover_ws/src/roverfinal/meshes/rueda5.STL</uri>
            </mesh>
          </geometry>
        </visual>
        <velocity_decay>
          <linear>0</linear>
          <angular>0</angular>
        </velocity_decay>
        <self_collide>0</self_collide>
        <kinematic>0</kinematic>
        <gravity>1</gravity>
      </link>
      <joint name='rueda_5' type='revolute'>
        <child>rueda5</child>
        <parent>rov</parent>
        <axis>
          <xyz>0 -1 -4e-06</xyz>
          <limit>
            <lower>-15</lower>
            <upper>15</upper>
            <effort>1000</effort>
            <velocity>0.5</velocity>
          </limit>
          <dynamics/>
        </axis>
      </joint>
      <link name='rueda6'>
        <pose>-0.39373 0.30621 0.12581 1.5708 -0 0</pose>
        <inertial>
          <pose>-9.8771e-06 -1.2449e-06 -0.00062163 0 -0 0</pose>
          <mass>3.6872</mass>
          <inertia>
            <ixx>0.01863</ixx>
            <ixy>1.0031e-07</ixy>
            <ixz>1.2633e-05</ixz>
            <iyy>0.018631</iyy>
            <iyz>1.7985e-06</iyz>
            <izz>0.02886</izz>
          </inertia>
        </inertial>
        <collision name='rueda6_collision'>
          <pose>0 0 0 0 -0 0</pose>
          <geometry>
            <mesh>
              <scale>1 1 1</scale>
              <uri>/home/daniela/proyrover_ws/src/roverfinal/meshes/rueda6.STL</uri>
            </mesh>
          </geometry>
          <max_contacts>10</max_contacts>
          <surface>
            <bounce/>
            <friction>
              <ode/>
            </friction>
            <contact>
              <ode/>
            </contact>
          </surface>
        </collision>
        <visual name='rueda6_visual'>
          <pose>0 0 0 0 -0 0</pose>
          <geometry>
            <mesh>
              <scale>1 1 1</scale>
              <uri>/home/daniela/proyrover_ws/src/roverfinal/meshes/rueda6.STL</uri>
            </mesh>
          </geometry>
        </visual>
        <velocity_decay>
          <linear>0</linear>
          <angular>0</angular>
        </velocity_decay>
        <self_collide>0</self_collide>
        <kinematic>0</kinematic>
        <gravity>1</gravity>
      </link>
      <joint name='rueda_6' type='revolute'>
        <child>rueda6</child>
        <parent>rov</parent>
        <axis>
          <xyz>0 -1 -4e-06</xyz>
          <limit>
            <lower>-15</lower>
            <upper>15</upper>
            <effort>1000</effort>
            <velocity>0.5</velocity>
          </limit>
          <dynamics/>
        </axis>
      </joint>
      <pose>0 0 0 0 -0 0</pose>
      <static>0</static>
    </model>
    <model name='asphalt_plane'>
      <static>1</static>
      <link name='link'>
        <collision name='collision'>
          <geometry>
            <box>
              <size>20 20 0.1</size>
            </box>
          </geometry>
          <max_contacts>10</max_contacts>
          <surface>
            <bounce/>
            <friction>
              <ode/>
            </friction>
            <contact>
              <ode/>
            </contact>
          </surface>
        </collision>
        <visual name='visual'>
          <cast_shadows>0</cast_shadows>
          <geometry>
            <box>
              <size>20 20 0.1</size>
            </box>
          </geometry>
          <material>
            <script>
              <uri>model://asphalt_plane/materials/scripts</uri>
              <uri>model://asphalt_plane/materials/textures</uri>
              <name>vrc/asphalt</name>
            </script>
          </material>
        </visual>
        <velocity_decay>
          <linear>0</linear>
          <angular>0</angular>
        </velocity_decay>
        <self_collide>0</self_collide>
        <kinematic>0</kinematic>
        <gravity>1</gravity>
      </link>
      <pose>0 0 0 0 -0 0</pose>
    </model>
    <state world_name='default'>
      <sim_time>265 787000000</sim_time>
      <real_time>326 693513413</real_time>
      <wall_time>1511150227 744466275</wall_time>
      <model name='asphalt_plane'>
        <pose>0 0 0 0 -0 0</pose>
        <link name='link'>
          <pose>0 0 0 0 -0 0</pose>
          <velocity>0 0 0 0 -0 0</velocity>
          <acceleration>0 0 0 0 -0 0</acceleration>
          <wrench>0 0 0 0 -0 0</wrench>
        </link>
      </model>
      <model name='ground_plane'>
        <pose>0 0 0 0 -0 0</pose>
        <link name='link'>
          <pose>0 0 0 0 -0 0</pose>
          <velocity>0 0 0 0 -0 0</velocity>
          <acceleration>0 0 0 0 -0 0</acceleration>
          <wrench>0 0 0 0 -0 0</wrench>
        </link>
      </model>
      <model name='roverfinal'>
        <pose>-0.027574 0.018186 0.044152 7e-06 -1e-05 0.02751</pose>
        <link name='rov'>
          <pose>-0.027574 0.018186 0.044152 7e-06 -1e-05 0.02751</pose>
          <velocity>-0.001032 7.2e-05 0.004429 -0.003615 0.010621 -0.000341</velocity>
          <acceleration>-2.05589 -0.554177 8.88125 -0.328787 1.00898 0.014513</acceleration>
          <wrench>-9.02883 -2.43377 39.0037 0 -0 0</wrench>
        </link>
        <link name='rueda1'>
          <pose>0.376428 -0.277024 0.169964 1.57081 -0.122362 0.027509</pose>
          <velocity>0.000237 0.000377 0.001189 -0.00316 0.001973 -0.000339</velocity>
          <acceleration>0.832383 0.501979 2.39234 -0.03228 0.007667 0.003384</acceleration>
          <wrench>3.06914 1.85089 8.82098 0 -0 0</wrench>
        </link>
        <link name='rueda2'>
          <pose>0.359582 0.335164 0.169968 1.5708 -0.217466 0.027509</pose>
          <velocity>0.000465 0.000444 -0.000916 -0.001709 -0.001062 -0.00025</velocity>
          <acceleration>0.580935 0.63773 -1.8564 -0.017162 -0.000441 0.004913</acceleration>
          <wrench>2.14202 2.35144 -6.84492 0 -0 0</wrench>
        </link>
        <link name='rueda3'>
          <pose>0.071427 -0.285416 0.16996 1.57081 -0.147054 0.027509</pose>
          <velocity>0.000262 0.000452 0.004345 -0.003765 0.002182 -0.000371</velocity>
          <acceleration>0.882581 0.374522 8.71468 -0.033715 0.006991 0.003115</acceleration>
          <wrench>3.25434 1.38097 32.1336 0 -0 0</wrench>
        </link>
        <link name='rueda4'>
          <pose>0.05458 0.326772 0.169965 1.57081 -0.066663 0.027509</pose>
          <velocity>0.000433 0.000488 0.002447 -0.003462 0.005278 -0.000422</velocity>
          <acceleration>0.541166 0.377261 4.88285 -0.033931 -0.00088 0.002292</acceleration>
          <wrench>1.99539 1.39104 18.004 0 -0 0</wrench>
        </link>
        <link name='rueda5'>
          <pose>-0.412734 -0.298739 0.169956 1.57081 -0.055073 0.027509</pose>
          <velocity>0.000192 0.000672 0.009703 -0.003411 0.003914 -0.000407</velocity>
          <acceleration>0.743656 0.221189 19.4896 -0.033754 -0.000877 0.002391</acceleration>
          <wrench>2.74201 0.815567 71.862 0 -0 0</wrench>
        </link>
        <link name='rueda6'>
          <pose>-0.429579 0.313449 0.16996 1.5708 0.017743 0.02751</pose>
          <velocity>0.000404 0.000584 0.007708 -0.00484 0.003368 -0.000274</velocity>
          <acceleration>0.51394 0.099338 15.4166 -0.042694 0.017574 0.003759</acceleration>
          <wrench>1.895 0.366281 56.8441 0 -0 0</wrench>
        </link>
      </model>
    </state>
    <gui fullscreen='0'>
      <camera name='user_camera'>
        <pose>46.0808 -26.4308 11.272 0 0.275643 2.35619</pose>
        <view_controller>orbit</view_controller>
      </camera>
    </gui>
  </world>
</sdf>
